<!DOCTYPE HTML PUBLIC "-//W3C//DTD HTML 4.01 Transitional//EN">
<HTML>
 <HEAD>
   <TITLE> Does the cancelation exception have a name?
   </TITLE>
   <LINK REL="Index" HREF="index.html" >
   <LINK REL="made" HREF="mailto:c%2B%2B-pthreads%40codesourcery.com?Subject=Re%3A%20Does%20the%20cancelation%20exception%20have%20a%20name%3F&In-Reply-To=%3C007b01c6fdea%249012bec0%246607a8c0%40pdimov2%3E">
   <META NAME="robots" CONTENT="index,nofollow">
   <style type="text/css">
       pre {
           white-space: pre-wrap;       /* css-2.1, curent FF, Opera, Safari */
           }
   </style>
   <META http-equiv="Content-Type" content="text/html; charset=us-ascii">
   
   <LINK REL="Next"  HREF="000594.html">
 </HEAD>
 <BODY BGCOLOR="#ffffff">
   <H1>Does the cancelation exception have a name?</H1>
    <B>Peter Dimov</B> 
    <A HREF="mailto:c%2B%2B-pthreads%40codesourcery.com?Subject=Re%3A%20Does%20the%20cancelation%20exception%20have%20a%20name%3F&In-Reply-To=%3C007b01c6fdea%249012bec0%246607a8c0%40pdimov2%3E"
       TITLE="Does the cancelation exception have a name?">pdimov at mmltd.net
       </A><BR>
    <I>Wed Nov  1 19:18:46 UTC 2006</I>
    <P><UL>
        
        <LI>Next message: <A HREF="000594.html">[c++-pthreads] Does the cancelation exception have a name?
</A></li>
         <LI> <B>Messages sorted by:</B> 
              <a href="date.html#593">[ date ]</a>
              <a href="thread.html#593">[ thread ]</a>
              <a href="subject.html#593">[ subject ]</a>
              <a href="author.html#593">[ author ]</a>
         </LI>
       </UL>
    <HR>  
<!--beginarticle-->
<PRE>Under the current NPTL implementation, can the cancelation exception be 
caught by name (and then rethrown)? If not, are there problems (technical or 
otherwise) with giving it a name so it can be caught?

Motivating example 1:

extern &quot;C&quot; int f() // C API, cancelation point
{
    try
    {
        cpp_implementation();
        return 0; // success
    }
    catch( cancel_exception )
    {
        throw;
    }
    catch( bad_alloc )
    {
        return ENOMEM;
    }
    catch( ... )
    {
        return -1;
    }
}

This is a function with a C interface and a C++ implementation. It 
translates all C++ exceptions into error codes, but the cancelation 
exception is special and needs to be rethrown, or else.

Motivating example 2:

void threadproc()
{
    try
    {
        store_result( user_function() );
    }
    catch( cancel_exception )
    {
        // record that the user task has been canceled
        throw;
    }
    catch( ... )
    {
        // record that the task terminated with an exception
    }
}

Here a user task is executed in a thread, and its result (which can be of an 
arbitrary type) is stored for later use. This enables usage of the form:

future&lt;int&gt; f = call_in_thread( user_function );

// do something to exploit parallelism

int r = f.get();

If the cancelation exception is and will remain unnamed, is it possible to 
provide a way to detect, in a catch( ... ) clause, whether the current 
exception is a cancelation exception? Something like

bool is_cancel_exception();

could also allow the two use patterns above.

Thanks in advance for any replies or comments. 


</PRE>

<!--endarticle-->
    <HR>
    <P><UL>
        <!--threads-->
	
	<LI>Next message: <A HREF="000594.html">[c++-pthreads] Does the cancelation exception have a name?
</A></li>
         <LI> <B>Messages sorted by:</B> 
              <a href="date.html#593">[ date ]</a>
              <a href="thread.html#593">[ thread ]</a>
              <a href="subject.html#593">[ subject ]</a>
              <a href="author.html#593">[ author ]</a>
         </LI>
       </UL>

<hr>
<a href="http://sourcerytools.com/cgi-bin/mailman/listinfo/c++-pthreads">More information about the c++-pthreads
mailing list</a><br>
</body></html>
