From scholar at drurl.us  Wed Mar 24 11:18:02 2010
From: scholar at drurl.us (Terrel Shumway)
Date: Wed, 24 Mar 2010 05:18:02 -0600
Subject: python2.4 setup.py check fails
Message-ID: <4BA9F4EA.807@drurl.us>

the try/except/finally form was introduced in 2.5. In 2.4 it is a syntax 
error.


Index: qm/test/target.py
===================================================================
--- qm/test/target.py   (revision 1085)
+++ qm/test/target.py   (working copy)
@@ -224,10 +224,11 @@
              result[Result.START_TIME] = qm.common.format_time_iso()
              # Run the test.
              try:
-                descriptor.Run(context, result)
-            except qm.common.Timeout, t:
-                result.SetOutcome(result.FAIL, 'Process timed out.')
-                result[Result.TIMEOUT_DETAIL] = str(t)
+                try:
+                    descriptor.Run(context, result)
+                except qm.common.Timeout, t:
+                    result.SetOutcome(result.FAIL, 'Process timed out.')
+                    result[Result.TIMEOUT_DETAIL] = str(t)
              finally:
                  # Note the end time.
                  result[Result.END_TIME] = qm.common.format_time_iso()


From matthias.braun at kit.edu  Wed Mar 31 15:05:28 2010
From: matthias.braun at kit.edu (Matthias Braun)
Date: Wed, 31 Mar 2010 17:05:28 +0200
Subject: qmtest create with invalid Label
Message-ID: <1270047928.5011.2.camel@i44pc66.info.uni-karlsruhe.de>

Just a small bugreport:

I have qmtest 2.4.1 running on ubuntu 9.10 here. When I run
	qmtest create --id=MYLABEL ...

and MYLABEL contains uppercase letters, then this seems to be considered
an InvalidLabel. Nonetheless a test is created on the disk but it will
never be listed in the test database later.

Greetings,
	Matthias Braun



